{"timestamp": "2024-09-01 15:50:27", "level": "ERROR", "message": "PostgresConnector.fetch_one raised an exception: PostgresConnector.fetch_one() missing 1 required positional argument: 'query'", "filename": "logging_decorator.py", "lineno": "-", "module": "-", "funcName": "-", "url": "-", "remote_addr": "-", "request_id": "-", "app_code": "application-X"}
{"timestamp": "2024-09-01 16:29:31", "level": "ERROR", "message": "PostgresConnector connection pool released", "filename": "postgres_connector.py", "lineno": 44, "module": "postgres_connector", "funcName": "close", "url": "-", "remote_addr": "-", "request_id": "-", "app_code": "application-X"}
{"timestamp": "2024-09-01 16:29:31", "level": "ERROR", "message": "PostgresConnector connection pool released", "filename": "postgres_connector.py", "lineno": 44, "module": "postgres_connector", "funcName": "close", "url": "-", "remote_addr": "-", "request_id": "-", "app_code": "application-X"}
{"timestamp": "2024-09-01 17:35:24", "level": "ERROR", "message": "Request parsing error: BaseResponse(message='whatever', data={'postgres': {'session_user': 'x_pgdb', 'current_database': 'x_pgdb'}, 'oracle': {'session_user': 'x_pgdb', 'current_database': 'x_pgdb'}, 'health': 'UP'})", "filename": "routes.py", "lineno": 38, "module": "routes", "funcName": "wrapped_func", "url": "http://localhost:5000/", "remote_addr": "127.0.0.1", "request_id": "8eeec0ee-2054-44f9-8d3f-42e9ddfc32d5", "app_code": "application-X"}
{"timestamp": "2024-09-01 17:41:24", "level": "ERROR", "message": "Response conversion error: 'BaseResponse' object has no attribute 'dict'", "filename": "routes.py", "lineno": 68, "module": "routes", "funcName": "wrapped_func", "url": "http://localhost:5000/?q=1234", "remote_addr": "127.0.0.1", "request_id": "18296bdb-fd83-4aae-81c8-9d2c120c9245", "app_code": "application-X"}
{"timestamp": "2024-09-01 17:41:25", "level": "ERROR", "message": "Response conversion error: 'BaseResponse' object has no attribute 'dict'", "filename": "routes.py", "lineno": 68, "module": "routes", "funcName": "wrapped_func", "url": "http://localhost:5000/?q=1234", "remote_addr": "127.0.0.1", "request_id": "b042ca57-c69c-4cf7-bbb7-cf55ce818b12", "app_code": "application-X"}
{"timestamp": "2024-09-01 17:51:59", "level": "ERROR", "message": "Unhandled exception: 404 Not Found: The requested URL was not found on the server. If you entered the URL manually please check your spelling and try again.", "filename": "middleware.py", "lineno": 54, "module": "middleware", "funcName": "handle_exception", "url": "http://localhost:5000/21324", "remote_addr": "127.0.0.1", "request_id": "5bb0a930-b0e1-4325-a002-ce78302270f9", "app_code": "application-X"}
{"timestamp": "2024-09-01 19:49:41", "level": "ERROR", "message": "Unhandled exception: 404 Not Found: The requested URL was not found on the server. If you entered the URL manually please check your spelling and try again.", "filename": "middleware.py", "lineno": 65, "module": "middleware", "funcName": "handle_generic_exception", "url": "http://localhost:5000/21324", "remote_addr": "127.0.0.1", "request_id": "cacb4d13-0f50-4d43-b439-7e0cc94f9cf5", "app_code": "application-X"}
{"timestamp": "2024-09-01 19:50:39", "level": "ERROR", "message": "Unhandled exception: 404 Not Found: The requested URL was not found on the server. If you entered the URL manually please check your spelling and try again.", "filename": "middleware.py", "lineno": 66, "module": "middleware", "funcName": "handle_generic_exception", "url": "http://localhost:5000/21324", "remote_addr": "127.0.0.1", "request_id": "6fd49c2c-5f03-4309-a62b-63a246336801", "app_code": "application-X"}
{"timestamp": "2024-09-01 19:51:57", "level": "ERROR", "message": "HTTPException: 404 Not Found: The requested URL was not found on the server. If you entered the URL manually please check your spelling and try again.", "filename": "middleware.py", "lineno": 61, "module": "middleware", "funcName": "handle_http_exception", "url": "http://localhost:5000/21324", "remote_addr": "127.0.0.1", "request_id": "3d92b4ed-6f75-46df-92d5-5148dee8865e", "app_code": "application-X"}
{"timestamp": "2024-09-01 19:52:32", "level": "ERROR", "message": "HTTPException: 404 Not Found: The requested URL was not found on the server. If you entered the URL manually please check your spelling and try again.", "filename": "middleware.py", "lineno": 61, "module": "middleware", "funcName": "handle_http_exception", "url": "http://localhost:5000/21324", "remote_addr": "127.0.0.1", "request_id": "15f9a4b2-37f4-4c63-9e10-a896739b193f", "app_code": "application-X"}
{"timestamp": "2024-09-01 19:55:43", "level": "ERROR", "message": "HTTPException: 404 Not Found: The requested URL was not found on the server. If you entered the URL manually please check your spelling and try again.", "filename": "middleware.py", "lineno": 61, "module": "middleware", "funcName": "handle_http_exception", "url": "http://localhost:5000/23243", "remote_addr": "127.0.0.1", "request_id": "c008cac9-8219-4950-91aa-a8fdffc2506c", "app_code": "application-X"}
{"timestamp": "2024-09-01 20:28:47", "level": "ERROR", "message": "Unhandled exception: 'dict' object has no attribute '__dict__'", "filename": "middleware.py", "lineno": 67, "module": "middleware", "funcName": "handle_generic_exception", "url": "http://localhost:5000/", "remote_addr": "127.0.0.1", "request_id": "4cc6ab0f-746d-4674-9b9e-25e996d12cba", "app_code": "application-X"}
{"timestamp": "2024-09-01 20:47:08", "level": "ERROR", "message": "Unhandled exception: 2 validation errors for ResponseModel\nmessage\n  Field required [type=missing, input_value={}, input_type=dict]\n    For further information visit https://errors.pydantic.dev/2.8/v/missing\ndata\n  Field required [type=missing, input_value={}, input_type=dict]\n    For further information visit https://errors.pydantic.dev/2.8/v/missing", "filename": "middleware.py", "lineno": 67, "module": "middleware", "funcName": "handle_generic_exception", "url": "http://localhost:5000/", "remote_addr": "127.0.0.1", "request_id": "81a43a6e-6d59-4909-a0f6-b5419c836a99", "app_code": "application-X"}
{"timestamp": "2024-09-01 20:47:40", "level": "ERROR", "message": "Unhandled exception: 2 validation errors for ResponseModel\nmessage\n  Field required [type=missing, input_value={}, input_type=dict]\n    For further information visit https://errors.pydantic.dev/2.8/v/missing\ndata\n  Field required [type=missing, input_value={}, input_type=dict]\n    For further information visit https://errors.pydantic.dev/2.8/v/missing", "filename": "middleware.py", "lineno": 67, "module": "middleware", "funcName": "handle_generic_exception", "url": "http://localhost:5000/", "remote_addr": "127.0.0.1", "request_id": "b590094a-8b98-4827-877a-13812eaaf052", "app_code": "application-X"}
{"timestamp": "2024-09-01 20:47:47", "level": "ERROR", "message": "Unhandled exception: 2 validation errors for ResponseModel\nmessage\n  Field required [type=missing, input_value={}, input_type=dict]\n    For further information visit https://errors.pydantic.dev/2.8/v/missing\ndata\n  Field required [type=missing, input_value={}, input_type=dict]\n    For further information visit https://errors.pydantic.dev/2.8/v/missing", "filename": "middleware.py", "lineno": 67, "module": "middleware", "funcName": "handle_generic_exception", "url": "http://localhost:5000/", "remote_addr": "127.0.0.1", "request_id": "fbc6a3ab-d9d2-4078-863d-8b9dd12b3f13", "app_code": "application-X"}
{"timestamp": "2024-09-01 20:48:59", "level": "ERROR", "message": "Unhandled exception: 2 validation errors for ResponseModel\nmessage\n  Field required [type=missing, input_value={}, input_type=dict]\n    For further information visit https://errors.pydantic.dev/2.8/v/missing\ndata\n  Field required [type=missing, input_value={}, input_type=dict]\n    For further information visit https://errors.pydantic.dev/2.8/v/missing", "filename": "middleware.py", "lineno": 67, "module": "middleware", "funcName": "handle_generic_exception", "url": "http://localhost:5000/", "remote_addr": "127.0.0.1", "request_id": "d2950e6e-7282-4788-be08-549ff63fea2e", "app_code": "application-X"}
{"timestamp": "2024-09-01 21:02:20", "level": "ERROR", "message": "Response serialization error: app.models.ResponseModel() argument after ** must be a mapping, not ResponseModel", "filename": "api_blueprint.py", "lineno": 99, "module": "api_blueprint", "funcName": "wrapped_func", "url": "http://localhost:5000/", "remote_addr": "127.0.0.1", "request_id": "d07cb8ae-3053-4860-b132-aa742e35a1a7", "app_code": "application-X"}
{"timestamp": "2024-09-01 23:29:28", "level": "ERROR", "message": "HTTPException: 404 Not Found: The requested URL was not found on the server. If you entered the URL manually please check your spelling and try again.", "filename": "middleware.py", "lineno": 61, "module": "middleware", "funcName": "handle_http_exception", "url": "http://localhost:5000/favicon.ico", "remote_addr": "127.0.0.1", "request_id": "c82665f2-ebdb-4e04-a82f-1877c209b4ff", "app_code": "application-X"}
{"timestamp": "2024-09-01 23:29:34", "level": "ERROR", "message": "HTTPException: 404 Not Found: The requested URL was not found on the server. If you entered the URL manually please check your spelling and try again.", "filename": "middleware.py", "lineno": 61, "module": "middleware", "funcName": "handle_http_exception", "url": "http://localhost:5000/user", "remote_addr": "127.0.0.1", "request_id": "7338a28d-c4a7-47f7-9ed4-7301b807bdb1", "app_code": "application-X"}
{"timestamp": "2024-09-01 23:34:49", "level": "ERROR", "message": "HTTPException: 404 Not Found: The requested URL was not found on the server. If you entered the URL manually please check your spelling and try again.", "filename": "middleware.py", "lineno": 61, "module": "middleware", "funcName": "handle_http_exception", "url": "http://localhost:5000/users", "remote_addr": "127.0.0.1", "request_id": "4917db50-ff61-455b-a1df-13fd0e97d171", "app_code": "application-X"}
{"timestamp": "2024-09-01 23:34:52", "level": "ERROR", "message": "Unhandled exception: app.models.UserModel() argument after ** must be a mapping, not str", "filename": "middleware.py", "lineno": 67, "module": "middleware", "funcName": "handle_generic_exception", "url": "http://localhost:5000/user", "remote_addr": "127.0.0.1", "request_id": "1c812b4f-45bd-47f3-97e4-00d984703ca4", "app_code": "application-X"}
{"timestamp": "2024-09-01 23:36:35", "level": "ERROR", "message": "Unhandled exception: 1 validation error for UserModel\ncreated_at\n  Input should be a valid string [type=string_type, input_value=datetime.datetime(2024, 9...o=datetime.timezone.utc), input_type=datetime]\n    For further information visit https://errors.pydantic.dev/2.8/v/string_type", "filename": "middleware.py", "lineno": 67, "module": "middleware", "funcName": "handle_generic_exception", "url": "http://localhost:5000/user", "remote_addr": "127.0.0.1", "request_id": "e9189586-a557-4c99-bcac-8462a82717b4", "app_code": "application-X"}
{"timestamp": "2024-09-01 23:49:14", "level": "ERROR", "message": "Unhandled exception: 'DBResponseModel' object has no attribute 'get'", "filename": "middleware.py", "lineno": 67, "module": "middleware", "funcName": "handle_generic_exception", "url": "http://localhost:5000/user", "remote_addr": "127.0.0.1", "request_id": "0ed60276-f99a-4e55-9eee-87260608dea1", "app_code": "application-X"}
